<robot name = "robot">
    <link name="Torso">
        <inertial>
            <origin xyz="0 0 0.5" rpy="0 0 0"/>
            <mass value="1" />
            <inertia ixx="100" ixy="0" ixz="0" iyy="100" iyz="0" izz="100" />
        </inertial>
        <visual>
            <origin xyz="0 0 0.5" rpy="0 0 0"/>
            <geometry>
                <box size="1 1 1" />
            </geometry>
            <material name="Cyan">
                <color rgba="0 1.0 1.0 1.0"/>
            </material>
        </visual>
        <collision>
            <origin xyz="0 0 0.5" rpy="0 0 0"/>
            <geometry>
                <box size="1 1 1" />
            </geometry>
        </collision>
    </link>
    <joint name="Torso_RightShoulder" type="revolute">
       <parent link="Torso"/>
       <child  link="RightShoulder"/>
       <origin rpy="0 0 0" xyz="0.5 0 0.95" />
       <axis xyz= "0 1 0"/>
       <limit effort="0.0" lower="-3.14159" upper="3.14159" velocity="0.0"/>
    </joint>
    <link name="RightShoulder">
        <inertial>
            <origin xyz="0.05 0 0" rpy="0 0 0"/>
            <mass value="1" />
            <inertia ixx="100" ixy="0" ixz="0" iyy="100" iyz="0" izz="100" />
        </inertial>
        <visual>
            <origin xyz="0.05 0 0" rpy="0 0 0"/>
            <geometry>
                <box size="0.1 0.1 0.1" />
            </geometry>
            <material name="Cyan">
                <color rgba="0 1.0 1.0 1.0"/>
            </material>
        </visual>
        <collision>
            <origin xyz="0.05 0 0" rpy="0 0 0"/>
            <geometry>
                <box size="0.1 0.1 0.1" />
            </geometry>
        </collision>
    </link>
    <joint name="RightShoulder_RightArm" type="revolute">
       <parent link="RightShoulder"/>
       <child  link="RightArm"/>
       <origin rpy="0 0 0" xyz="0.1 0 0" />
       <axis xyz= "0 0 1"/>
       <limit effort="0.0" lower="-3.14159" upper="3.14159" velocity="0.0"/>
    </joint>
    <link name="RightArm">
        <inertial>
            <origin xyz="0.5 0 0" rpy="0 0 0"/>
            <mass value="1" />
            <inertia ixx="100" ixy="0" ixz="0" iyy="100" iyz="0" izz="100" />
        </inertial>
        <visual>
            <origin xyz="0.5 0 0" rpy="0 0 0"/>
            <geometry>
                <box size="1 0.25 0.25" />
            </geometry>
            <material name="Cyan">
                <color rgba="0 1.0 1.0 1.0"/>
            </material>
        </visual>
        <collision>
            <origin xyz="0.5 0 0" rpy="0 0 0"/>
            <geometry>
                <box size="1 0.25 0.25" />
            </geometry>
        </collision>
    </link>
    <joint name="Torso_LeftShoulder" type="revolute">
       <parent link="Torso"/>
       <child  link="LeftShoulder"/>
       <origin rpy="0 0 0" xyz="-0.5 0 0.95" />
       <axis xyz= "0 1 0"/>
       <limit effort="0.0" lower="-3.14159" upper="3.14159" velocity="0.0"/>
    </joint>
    <link name="LeftShoulder">
        <inertial>
            <origin xyz="-0.05 0 0" rpy="0 0 0"/>
            <mass value="1" />
            <inertia ixx="100" ixy="0" ixz="0" iyy="100" iyz="0" izz="100" />
        </inertial>
        <visual>
            <origin xyz="-0.05 0 0" rpy="0 0 0"/>
            <geometry>
                <box size="0.1 0.1 0.1" />
            </geometry>
            <material name="Cyan">
                <color rgba="0 1.0 1.0 1.0"/>
            </material>
        </visual>
        <collision>
            <origin xyz="-0.05 0 0" rpy="0 0 0"/>
            <geometry>
                <box size="0.1 0.1 0.1" />
            </geometry>
        </collision>
    </link>
    <joint name="LeftShoulder_LeftArm" type="revolute">
       <parent link="LeftShoulder"/>
       <child  link="LeftArm"/>
       <origin rpy="0 0 0" xyz="-0.1 0 0" />
       <axis xyz= "0 0 1"/>
       <limit effort="0.0" lower="-3.14159" upper="3.14159" velocity="0.0"/>
    </joint>
    <link name="LeftArm">
        <inertial>
            <origin xyz="-0.5 0 0" rpy="0 0 0"/>
            <mass value="1" />
            <inertia ixx="100" ixy="0" ixz="0" iyy="100" iyz="0" izz="100" />
        </inertial>
        <visual>
            <origin xyz="-0.5 0 0" rpy="0 0 0"/>
            <geometry>
                <box size="1 0.25 0.25" />
            </geometry>
            <material name="Cyan">
                <color rgba="0 1.0 1.0 1.0"/>
            </material>
        </visual>
        <collision>
            <origin xyz="-0.5 0 0" rpy="0 0 0"/>
            <geometry>
                <box size="1 0.25 0.25" />
            </geometry>
        </collision>
    </link>
</robot>